Workbook

Sheet Executive Summary
A1: EcoConnect Faridabad - Data Verification Summary
A2: Research and review artifact for Member 3 (Data, QA & Demo Lead). It is NOT an authorization to publish any provider, and it does not change the production dataset.
A3: All counts below are formulas over the Candidate Register and Verification Evidence sheets. Review date 2026-10-10.
A5: 1. Candidate-level result
A6: Overall status (see Data Dictionary for the rule) | B6: Candidates
A7: verified | B7: =COUNTIF('Candidate Register'!$W$5:$W$14,"verified") -> 0
A8: partially_verified | B8: =COUNTIF('Candidate Register'!$W$5:$W$14,"partially_verified") -> 3
A9: unverified | B9: =COUNTIF('Candidate Register'!$W$5:$W$14,"unverified") -> 7
A10: conflicting | B10: =COUNTIF('Candidate Register'!$W$5:$W$14,"conflicting") -> 0
A11: Total candidate records | B11: =COUNTA('Candidate Register'!$A$5:$A$14) -> 10
A13: 2. Checks by category (all candidates)
A14: Verification category | B14: verified | C14: partially_verified | D14: unverified | E14: conflicting | F14: not_applicable | G14: Total | H14: Outstanding
A15: Entity match to historical record | B15: =COUNTIFS('Verification Evidence'!$C$5:$C$94,$A15,'Verification Evidence'!$D$5:$D$94,"verified") -> 0 | C15: =COUNTIFS('Verification Evidence'!$C$5:$C$94,$A15,'Verification Evidence'!$D$5:$D$94,"partially_verified") -> 9 | D15: =COUNTIFS('Verification Evidence'!$C$5:$C$94,$A15,'Verification Evidence'!$D$5:$D$94,"unverified") -> 1 | E15: =COUNTIFS('Verification Evidence'!$C$5:$C$94,$A15,'Verification Evidence'!$D$5:$D$94,"conflicting") -> 0 | F15: =COUNTIFS('Verification Evidence'!$C$5:$C$94,$A15,'Verification Evidence'!$D$5:$D$94,"not_applicable") -> 0 | G15: =SUM(B15:F15) -> 10 | H15: =G15-B15-F15 -> 10
A16: Current registration / authorization | B16: =COUNTIFS('Verification Evidence'!$C$5:$C$94,$A16,'Verification Evidence'!$D$5:$D$94,"verified") -> 0 | C16: =COUNTIFS('Verification Evidence'!$C$5:$C$94,$A16,'Verification Evidence'!$D$5:$D$94,"partially_verified") -> 3 | D16: =COUNTIFS('Verification Evidence'!$C$5:$C$94,$A16,'Verification Evidence'!$D$5:$D$94,"unverified") -> 7 | E16: =COUNTIFS('Verification Evidence'!$C$5:$C$94,$A16,'Verification Evidence'!$D$5:$D$94,"conflicting") -> 0 | F16: =COUNTIFS('Verification Evidence'!$C$5:$C$94,$A16,'Verification Evidence'!$D$5:$D$94,"not_applicable") -> 0 | G16: =SUM(B16:F16) -> 10 | H16: =G16-B16-F16 -> 10
A17: Operating at recorded address | B17: =COUNTIFS('Verification Evidence'!$C$5:$C$94,$A17,'Verification Evidence'!$D$5:$D$94,"verified") -> 0 | C17: =COUNTIFS('Verification Evidence'!$C$5:$C$94,$A17,'Verification Evidence'!$D$5:$D$94,"partially_verified") -> 2 | D17: =COUNTIFS('Verification Evidence'!$C$5:$C$94,$A17,'Verification Evidence'!$D$5:$D$94,"unverified") -> 8 | E17: =COUNTIFS('Verification Evidence'!$C$5:$C$94,$A17,'Verification Evidence'!$D$5:$D$94,"conflicting") -> 0 | F17: =COUNTIFS('Verification Evidence'!$C$5:$C$94,$A17,'Verification Evidence'!$D$5:$D$94,"not_applicable") -> 0 | G17: =SUM(B17:F17) -> 10 | H17: =G17-B17-F17 -> 10
A18: Household (individual) intake | B18: =COUNTIFS('Verification Evidence'!$C$5:$C$94,$A18,'Verification Evidence'!$D$5:$D$94,"verified") -> 0 | C18: =COUNTIFS('Verification Evidence'!$C$5:$C$94,$A18,'Verification Evidence'!$D$5:$D$94,"partially_verified") -> 0 | D18: =COUNTIFS('Verification Evidence'!$C$5:$C$94,$A18,'Verification Evidence'!$D$5:$D$94,"unverified") -> 10 | E18: =COUNTIFS('Verification Evidence'!$C$5:$C$94,$A18,'Verification Evidence'!$D$5:$D$94,"conflicting") -> 0 | F18: =COUNTIFS('Verification Evidence'!$C$5:$C$94,$A18,'Verification Evidence'!$D$5:$D$94,"not_applicable") -> 0 | G18: =SUM(B18:F18) -> 10 | H18: =G18-B18-F18 -> 10
A19: Drop-off / collection / pickup service | B19: =COUNTIFS('Verification Evidence'!$C$5:$C$94,$A19,'Verification Evidence'!$D$5:$D$94,"verified") -> 0 | C19: =COUNTIFS('Verification Evidence'!$C$5:$C$94,$A19,'Verification Evidence'!$D$5:$D$94,"partially_verified") -> 2 | D19: =COUNTIFS('Verification Evidence'!$C$5:$C$94,$A19,'Verification Evidence'!$D$5:$D$94,"unverified") -> 8 | E19: =COUNTIFS('Verification Evidence'!$C$5:$C$94,$A19,'Verification Evidence'!$D$5:$D$94,"conflicting") -> 0 | F19: =COUNTIFS('Verification Evidence'!$C$5:$C$94,$A19,'Verification Evidence'!$D$5:$D$94,"not_applicable") -> 0 | G19: =SUM(B19:F19) -> 10 | H19: =G19-B19-F19 -> 10
A20: Accepted item categories | B20: =COUNTIFS('Verification Evidence'!$C$5:$C$94,$A20,'Verification Evidence'!$D$5:$D$94,"verified") -> 0 | C20: =COUNTIFS('Verification Evidence'!$C$5:$C$94,$A20,'Verification Evidence'!$D$5:$D$94,"partially_verified") -> 0 | D20: =COUNTIFS('Verification Evidence'!$C$5:$C$94,$A20,'Verification Evidence'!$D$5:$D$94,"unverified") -> 10 | E20: =COUNTIFS('Verification Evidence'!$C$5:$C$94,$A20,'Verification Evidence'!$D$5:$D$94,"conflicting") -> 0 | F20: =COUNTIFS('Verification Evidence'!$C$5:$C$94,$A20,'Verification Evidence'!$D$5:$D$94,"not_applicable") -> 0 | G20: =SUM(B20:F20) -> 10 | H20: =G20-B20-F20 -> 10
A21: Contact channel | B21: =COUNTIFS('Verification Evidence'!$C$5:$C$94,$A21,'Verification Evidence'!$D$5:$D$94,"verified") -> 0 | C21: =COUNTIFS('Verification Evidence'!$C$5:$C$94,$A21,'Verification Evidence'!$D$5:$D$94,"partially_verified") -> 2 | D21: =COUNTIFS('Verification Evidence'!$C$5:$C$94,$A21,'Verification Evidence'!$D$5:$D$94,"unverified") -> 8 | E21: =COUNTIFS('Verification Evidence'!$C$5:$C$94,$A21,'Verification Evidence'!$D$5:$D$94,"conflicting") -> 0 | F21: =COUNTIFS('Verification Evidence'!$C$5:$C$94,$A21,'Verification Evidence'!$D$5:$D$94,"not_applicable") -> 0 | G21: =SUM(B21:F21) -> 10 | H21: =G21-B21-F21 -> 10
A22: Operating hours | B22: =COUNTIFS('Verification Evidence'!$C$5:$C$94,$A22,'Verification Evidence'!$D$5:$D$94,"verified") -> 0 | C22: =COUNTIFS('Verification Evidence'!$C$5:$C$94,$A22,'Verification Evidence'!$D$5:$D$94,"partially_verified") -> 0 | D22: =COUNTIFS('Verification Evidence'!$C$5:$C$94,$A22,'Verification Evidence'!$D$5:$D$94,"unverified") -> 10 | E22: =COUNTIFS('Verification Evidence'!$C$5:$C$94,$A22,'Verification Evidence'!$D$5:$D$94,"conflicting") -> 0 | F22: =COUNTIFS('Verification Evidence'!$C$5:$C$94,$A22,'Verification Evidence'!$D$5:$D$94,"not_applicable") -> 0 | G22: =SUM(B22:F22) -> 10 | H22: =G22-B22-F22 -> 10
A23: Listing & reuse permission | B23: =COUNTIFS('Verification Evidence'!$C$5:$C$94,$A23,'Verification Evidence'!$D$5:$D$94,"verified") -> 0 | C23: =COUNTIFS('Verification Evidence'!$C$5:$C$94,$A23,'Verification Evidence'!$D$5:$D$94,"partially_verified") -> 0 | D23: =COUNTIFS('Verification Evidence'!$C$5:$C$94,$A23,'Verification Evidence'!$D$5:$D$94,"unverified") -> 10 | E23: =COUNTIFS('Verification Evidence'!$C$5:$C$94,$A23,'Verification Evidence'!$D$5:$D$94,"conflicting") -> 0 | F23: =COUNTIFS('Verification Evidence'!$C$5:$C$94,$A23,'Verification Evidence'!$D$5:$D$94,"not_applicable") -> 0 | G23: =SUM(B23:F23) -> 10 | H23: =G23-B23-F23 -> 10
A24: All checks | B24: =SUM(B15:B23) -> 0 | C24: =SUM(C15:C23) -> 18 | D24: =SUM(D15:D23) -> 72 | E24: =SUM(E15:E23) -> 0 | F24: =SUM(F15:F23) -> 0 | G24: =SUM(G15:G23) -> 90 | H24: =SUM(H15:H23) -> 90
A25: Outstanding = checks not yet 'verified' and not 'not_applicable'. 'Completed' below means status 'verified'.
A27: 3. Headline checks: completed versus outstanding
A28: Check | B28: Completed (verified) | C28: Outstanding | D28: Of which partially verified
A29: Current registration | B29: =B16 -> 0 | C29: =H16 -> 10 | D29: =C16 -> 3
A30: Household acceptance | B30: =B18 -> 0 | C30: =H18 -> 10 | D30: =C18 -> 0
A31: Contact channel | B31: =B21 -> 0 | C31: =H21 -> 10 | D31: =C21 -> 2
A32: Operating hours | B32: =B22 -> 0 | C32: =H22 -> 10 | D32: =C22 -> 0
A33: Listing / reuse permission | B33: =B23 -> 0 | C33: =H23 -> 10 | D33: =C23 -> 0
A35: 4. Production-safety checks (all expected to stay as shown)
A36: Check | B36: Count | C36: Expected
A37: Records with active = True | B37: =COUNTIF('Candidate Register'!$U$5:$U$14,"True") -> 0 | C37: 0
A38: Records with review_status other than pending | B38: =COUNTA('Candidate Register'!$R$5:$R$14)-COUNTIF('Candidate Register'!$R$5:$R$14,"pending") -> 0 | C38: 0
A39: Records with isSample = True | B39: =COUNTIF('Candidate Register'!$T$5:$T$14,"True") -> 0 | C39: 0
A40: Records with listing_permission other than pending_clarification | B40: =COUNTA('Candidate Register'!$P$5:$P$14)-COUNTIF('Candidate Register'!$P$5:$P$14,"pending_clarification") -> 0 | C40: 0
A41: Candidates needing human follow-up (any open check) | B41: =SUMPRODUCT(--(COUNTIFS('Verification Evidence'!$A$5:$A$94,'Candidate Register'!$A$5:$A$14,'Verification Evidence'!$M$5:$M$94,"human_verification_required")>0)) -> 10 | C41: 10
A43: 5. Reconciliation checks
A44: Check | B44: Result | C44: Expected
A45: Candidate rows in register | B45: =COUNTA('Candidate Register'!$A$5:$A$14) -> 10 | C45: 10
...

Sheet Candidate Register
A1: Candidate Register
A2: Columns A-V are the original CSV exactly as supplied (10 rows x 22 columns). Columns W-AB (blue headers) are separate, derived verification fields. The source CSV was not modified.
A3: Amber-shaded empty cells were blank in the source CSV. active=False and review_status=pending are kept for every record: quarantined research data, not for publication.
A4: provider_id | B4: provider_name | C4: provider_type_as_listed | D4: address_as_listed | E4: accepted_item_types | F4: service_modes | G4: source_url | H4: source_title | I4: source_accessed_at | J4: source_publication_date | K4: registration_status | L4: verification_level | M4: verification_method | N4: verification_evidence_ref | O4: source_license | P4: listing_permission | Q4: contact_confirmation | R4: review_status | S4: last_verified_at | T4: isSample | U4: active | V4: notes | W4: derived_overall_status | X4: derived_registration_status | Y4: derived_household_status | Z4: derived_cpcb2023_haryana_serial | AA4: derived_cpcb2023_capacity_mta | AB4: derived_flags
A5: FBD-EW-HSPCB-HIST-016 | B5: Endeavor Re-processor and Recyclers India | C5: Dismantler | D5: Plot no. 323, Sec-24, Industrial Area, Faridabad | G5: https://hspcb.gov.in/uploads/pages/ewaster_66ac829eb3965.pdf | H5: HSPCB PDF: List of E-waste Recyclers / Dismantler (historical record; current validity not established) | I5: 46304 | J5: Not established from accessible record | K5: unknown_needs_current_verification | L5: official_historical_record_only | M5: official_document_search_result | N5: HSPCB PDF row 16 (indexed search extract) | O5: not_checked | P5: pending_clarification | Q5: not_checked | R5: pending | T5: False | U5: False | V5: Do not publish as currently authorized until current CPCB registration/status and service details are verified. | W5: =IF(COUNTIFS('Verification Evidence'!$A$5:$A$94,$A5,'Verification Evidence'!$D$5:$D$94,"conflicting")>0,"conflicting",IF(COUNTIFS('Verification Evidence'!$A$5:$A$94,$A5,'Verification Evidence'!$D$5:$D$94,"verified")+COUNTIFS('Verification Evidence'!$A$5:$A$94,$A5,'Verification Evidence'!$D$5:$D$94,"not_applicable")=9,"verified",IF(COUNTIFS('Verification Evidence'!$A$5:$A$94,$A5,'Verification Evidence'!$C$5:$C$94,"Current registration / authorization",'Verification Evidence'!$D$5:$D$94,"verified")+COUNTIFS('Verification Evidence'!$A$5:$A$94,$A5,'Verification Evidence'!$C$5:$C$94,"Current registration / authorization",'Verification Evidence'!$D$5:$D$94,"partially_verified")+COUNTIFS('Verification Evidence'!$A$5:$A$94,$A5,'Verification Evidence'!$C$5:$C$94,"Operating at recorded address",'Verification Evidence'!$D$5:$D$94,"verified")+COUNTIFS('Verification Evidence'!$A$5:$A$94,$A5,'Verification Evidence'!$C$5:$C$94,"Operating at recorded address",'Verification Evidence'!$D$5:$D$94,"partially_verified")>0,"partially_verified","unverified"))) -> unverified | X5: =IFERROR(INDEX('Verification Evidence'!$D$5:$D$94,MATCH($A5&"|Current registration / authorization",'Verification Evidence'!$P$5:$P$94,0)),"MISSING") -> unverified | Y5: =IFERROR(INDEX('Verification Evidence'!$D$5:$D$94,MATCH($A5&"|Household (individual) intake",'Verification Evidence'!$P$5:$P$94,0)),"MISSING") -> unverified | Z5: 12 | AA5: 365 | AB5: Shares plot 323, Sec-24 with HIST-021; CPCB list annotation 'Not available on website'; similarly named entity in Rohtak not matched.
A6: FBD-EW-HSPCB-HIST-017 | B6: A to Z E-waste Solutions | C6: Dismantler | D6: Plot no. 66, Pargiti Vihar, Industrial Area, Sector-59, Ballabgarh, Faridabad | G6: https://hspcb.gov.in/uploads/pages/ewaster_66ac829eb3965.pdf | H6: HSPCB PDF: List of E-waste Recyclers / Dismantler (historical record; current validity not established) | I6: 46304 | J6: Not established from accessible record | K6: unknown_needs_current_verification | L6: official_historical_record_only | M6: official_document_search_result | N6: HSPCB PDF row 17 (indexed search extract) | O6: not_checked | P6: pending_clarification | Q6: not_checked | R6: pending | T6: False | U6: False | V6: Do not publish as currently authorized until current CPCB registration/status and service details are verified. | W6: =IF(COUNTIFS('Verification Evidence'!$A$5:$A$94,$A6,'Verification Evidence'!$D$5:$D$94,"conflicting")>0,"conflicting",IF(COUNTIFS('Verification Evidence'!$A$5:$A$94,$A6,'Verification Evidence'!$D$5:$D$94,"verified")+COUNTIFS('Verification Evidence'!$A$5:$A$94,$A6,'Verification Evidence'!$D$5:$D$94,"not_applicable")=9,"verified",IF(COUNTIFS('Verification Evidence'!$A$5:$A$94,$A6,'Verification Evidence'!$C$5:$C$94,"Current registration / authorization",'Verification Evidence'!$D$5:$D$94,"verified")+COUNTIFS('Verification Evidence'!$A$5:$A$94,$A6,'Verification Evidence'!$C$5:$C$94,"Current registration / authorization",'Verification Evidence'!$D$5:$D$94,"partially_verified")+COUNTIFS('Verification Evidence'!$A$5:$A$94,$A6,'Verification Evidence'!$C$5:$C$94,"Operating at recorded address",'Verification Evidence'!$D$5:$D$94,"verified")+COUNTIFS('Verification Evidence'!$A$5:$A$94,$A6,'Verification Evidence'!$C$5:$C$94,"Operating at recorded address",'Verification Evidence'!$D$5:$D$94,"partially_verified")>0,"partially_verified","unverified"))) -> unverified | X6: =IFERROR(INDEX('Verification Evidence'!$D$5:$D$94,MATCH($A6&"|Current registration / authorization",'Verification Evidence'!$P$5:$P$94,0)),"MISSING") -> unverified | Y6: =IFERROR(INDEX('Verification Evidence'!$D$5:$D$94,MATCH($A6&"|Household (individual) intake",'Verification Evidence'!$P$5:$P$94,0)),"MISSING") -> unverified | Z6: not found in list | AA6: n/a | AB6: Not found in CPCB 2023 Haryana list; 'Pargiti Vihar' may be a variant of 'Pragati Vihar' (unconfirmed, not corrected).
A7: FBD-EW-HSPCB-HIST-018 | B7: E-waste Solutions | C7: Dismantler | D7: Industrial Shed, 1A, Industrial Estate, Sector-6, Faridabad | G7: https://hspcb.gov.in/uploads/pages/ewaster_66ac829eb3965.pdf | H7: HSPCB PDF: List of E-waste Recyclers / Dismantler (historical record; current validity not established) | I7: 46304 | J7: Not established from accessible record | K7: unknown_needs_current_verification | L7: official_historical_record_only | M7: official_document_search_result | N7: HSPCB PDF row 18 (indexed search extract) | O7: not_checked | P7: pending_clarification | Q7: not_checked | R7: pending | T7: False | U7: False | V7: Do not publish as currently authorized until current CPCB registration/status and service details are verified. | W7: =IF(COUNTIFS('Verification Evidence'!$A$5:$A$94,$A7,'Verification Evidence'!$D$5:$D$94,"conflicting")>0,"conflicting",IF(COUNTIFS('Verification Evidence'!$A$5:$A$94,$A7,'Verification Evidence'!$D$5:$D$94,"verified")+COUNTIFS('Verification Evidence'!$A$5:$A$94,$A7,'Verification Evidence'!$D$5:$D$94,"not_applicable")=9,"verified",IF(COUNTIFS('Verification Evidence'!$A$5:$A$94,$A7,'Verification Evidence'!$C$5:$C$94,"Current registration / authorization",'Verification Evidence'!$D$5:$D$94,"verified")+COUNTIFS('Verification Evidence'!$A$5:$A$94,$A7,'Verification Evidence'!$C$5:$C$94,"Current registration / authorization",'Verification Evidence'!$D$5:$D$94,"partially_verified")+COUNTIFS('Verification Evidence'!$A$5:$A$94,$A7,'Verification Evidence'!$C$5:$C$94,"Operating at recorded address",'Verification Evidence'!$D$5:$D$94,"verified")+COUNTIFS('Verification Evidence'!$A$5:$A$94,$A7,'Verification Evidence'!$C$5:$C$94,"Operating at recorded address",'Verification Evidence'!$D$5:$D$94,"partially_verified")>0,"partially_verified","unverified"))) -> partially_verified | X7: =IFERROR(INDEX('Verification Evidence'!$D$5:$D$94,MATCH($A7&"|Current registration / authorization",'Verification Evidence'!$P$5:$P$94,0)),"MISSING") -> partially_verified | Y7: =IFERROR(INDEX('Verification Evidence'!$D$5:$D$94,MATCH($A7&"|Household (individual) intake",'Verification Evidence'!$P$5:$P$94,0)),"MISSING") -> unverified | Z7: 13 | AA7: 1000 | AB7: Generic name; a differently addressed 'E waste Solutions' appears in 2025 HSPCB fragment - do not conflate.
A8: FBD-EW-HSPCB-HIST-019 | B8: V S Enterprises | C8: Dismantler | D8: Plot no. 9, Pragati Vihar, Sector-59, Faridabad | G8: https://hspcb.gov.in/uploads/pages/ewaster_66ac829eb3965.pdf | H8: HSPCB PDF: List of E-waste Recyclers / Dismantler (historical record; current validity not established) | I8: 46304 | J8: Not established from accessible record | K8: unknown_needs_current_verification | L8: official_historical_record_only | M8: official_document_search_result | N8: HSPCB PDF row 19 (indexed search extract) | O8: not_checked | P8: pending_clarification | Q8: not_checked | R8: pending | T8: False | U8: False | V8: Do not publish as currently authorized until current CPCB registration/status and service details are verified. | W8: =IF(COUNTIFS('Verification Evidence'!$A$5:$A$94,$A8,'Verification Evidence'!$D$5:$D$94,"conflicting")>0,"conflicting",IF(COUNTIFS('Verification Evidence'!$A$5:$A$94,$A8,'Verification Evidence'!$D$5:$D$94,"verified")+COUNTIFS('Verification Evidence'!$A$5:$A$94,$A8,'Verification Evidence'!$D$5:$D$94,"not_applicable")=9,"verified",IF(COUNTIFS('Verification Evidence'!$A$5:$A$94,$A8,'Verification Evidence'!$C$5:$C$94,"Current registration / authorization",'Verification Evidence'!$D$5:$D$94,"verified")+COUNTIFS('Verification Evidence'!$A$5:$A$94,$A8,'Verification Evidence'!$C$5:$C$94,"Current registration / authorization",'Verification Evidence'!$D$5:$D$94,"partially_verified")+COUNTIFS('Verification Evidence'!$A$5:$A$94,$A8,'Verification Evidence'!$C$5:$C$94,"Operating at recorded address",'Verification Evidence'!$D$5:$D$94,"verified")+COUNTIFS('Verification Evidence'!$A$5:$A$94,$A8,'Verification Evidence'!$C$5:$C$94,"Operating at recorded address",'Verification Evidence'!$D$5:$D$94,"partially_verified")>0,"partially_verified","unverified"))) -> unverified | X8: =IFERROR(INDEX('Verification Evidence'!$D$5:$D$94,MATCH($A8&"|Current registration / authorization",'Verification Evidence'!$P$5:$P$94,0)),"MISSING") -> unverified | Y8: =IFERROR(INDEX('Verification Evidence'!$D$5:$D$94,MATCH($A8&"|Household (individual) intake",'Verification Evidence'!$P$5:$P$94,0)),"MISSING") -> unverified | Z8: 14 | AA8: 300 | AB8: CPCB list annotation 'Not available on website'; no independent web presence found.
A9: FBD-EW-HSPCB-HIST-020 | B9: AMN E-Waste Management Pvt Ltd. | C9: Dismantler | D9: Plot No. 171, Sector-59, Industrial Area, Faridabad | G9: https://hspcb.gov.in/uploads/pages/ewaster_66ac829eb3965.pdf | H9: HSPCB PDF: List of E-waste Recyclers / Dismantler (historical record; current validity not established) | I9: 46304 | J9: Not established from accessible record | K9: unknown_needs_current_verification | L9: official_historical_record_only | M9: official_document_search_result | N9: HSPCB PDF row 20 (indexed search extract) | O9: not_checked | P9: pending_clarification | Q9: not_checked | R9: pending | T9: False | U9: False | V9: Do not publish as currently authorized until current CPCB registration/status and service details are verified. | W9: =IF(COUNTIFS('Verification Evidence'!$A$5:$A$94,$A9,'Verification Evidence'!$D$5:$D$94,"conflicting")>0,"conflicting",IF(COUNTIFS('Verification Evidence'!$A$5:$A$94,$A9,'Verification Evidence'!$D$5:$D$94,"verified")+COUNTIFS('Verification Evidence'!$A$5:$A$94,$A9,'Verification Evidence'!$D$5:$D$94,"not_applicable")=9,"verified",IF(COUNTIFS('Verification Evidence'!$A$5:$A$94,$A9,'Verification Evidence'!$C$5:$C$94,"Current registration / authorization",'Verification Evidence'!$D$5:$D$94,"verified")+COUNTIFS('Verification Evidence'!$A$5:$A$94,$A9,'Verification Evidence'!$C$5:$C$94,"Current registration / authorization",'Verification Evidence'!$D$5:$D$94,"partially_verified")+COUNTIFS('Verification Evidence'!$A$5:$A$94,$A9,'Verification Evidence'!$C$5:$C$94,"Operating at recorded address",'Verification Evidence'!$D$5:$D$94,"verified")+COUNTIFS('Verification Evidence'!$A$5:$A$94,$A9,'Verification Evidence'!$C$5:$C$94,"Operating at recorded address",'Verification Evidence'!$D$5:$D$94,"partially_verified")>0,"partially_verified","unverified"))) -> unverified | X9: =IFERROR(INDEX('Verification Evidence'!$D$5:$D$94,MATCH($A9&"|Current registration / authorization",'Verification Evidence'!$P$5:$P$94,0)),"MISSING") -> unverified | Y9: =IFERROR(INDEX('Verification Evidence'!$D$5:$D$94,MATCH($A9&"|Household (individual) intake",'Verification Evidence'!$P$5:$P$94,0)),"MISSING") -> unverified | Z9: 11 | AA9: 290 | AB9: CPCB list annotation 'Not available on website'; no independent web presence found.
A10: FBD-EW-HSPCB-HIST-021 | B10: Naturevolt Recyclers India Pvt Ltd | C10: Recycler | D10: Plot No. 323, Part-IV, Sector-24, Faridabad | G10: https://hspcb.gov.in/uploads/pages/ewaster_66ac829eb3965.pdf | H10: HSPCB PDF: List of E-waste Recyclers / Dismantler (historical record; current validity not established) | I10: 46304 | J10: Not established from accessible record | K10: unknown_needs_current_verification | L10: official_historical_record_only | M10: official_document_search_result | N10: HSPCB PDF row 21 (indexed search extract) | O10: not_checked | P10: pending_clarification | Q10: not_checked | R10: pending | T10: False | U10: False | V10: Do not publish as currently authorized until current CPCB registration/status and service details are verified. | W10: =IF(COUNTIFS('Verification Evidence'!$A$5:$A$94,$A10,'Verification Evidence'!$D$5:$D$94,"conflicting")>0,"conflicting",IF(COUNTIFS('Verification Evidence'!$A$5:$A$94,$A10,'Verification Evidence'!$D$5:$D$94,"verified")+COUNTIFS('Verification Evidence'!$A$5:$A$94,$A10,'Verification Evidence'!$D$5:$D$94,"not_applicable")=9,"verified",IF(COUNTIFS('Verification Evidence'!$A$5:$A$94,$A10,'Verification Evidence'!$C$5:$C$94,"Current registration / authorization",'Verification Evidence'!$D$5:$D$94,"verified")+COUNTIFS('Verification Evidence'!$A$5:$A$94,$A10,'Verification Evidence'!$C$5:$C$94,"Current registration / authorization",'Verification Evidence'!$D$5:$D$94,"partially_verified")+COUNTIFS('Verification Evidence'!$A$5:$A$94,$A10,'Verification Evidence'!$C$5:$C$94,"Operating at recorded address",'Verification Evidence'!$D$5:$D$94,"verified")+COUNTIFS('Verification Evidence'!$A$5:$A$94,$A10,'Verification Evidence'!$C$5:$C$94,"Operating at recorded address",'Verification Evidence'!$D$5:$D$94,"partially_verified")>0,"partially_verified","unverified"))) -> partially_verified | X10: =IFERROR(INDEX('Verification Evidence'!$D$5:$D$94,MATCH($A10&"|Current registration / authorization",'Verification Evidence'!$P$5:$P$94,0)),"MISSING") -> partially_verified | Y10: =IFERROR(INDEX('Verification Evidence'!$D$5:$D$94,MATCH($A10&"|Household (individual) intake",'Verification Evidence'!$P$5:$P$94,0)),"MISSING") -> unverified | Z10: 36 | AA10: 5400 | AB10: Shares plot 323 with HIST-016; two Naturevolt units appear in 2025 HSPCB fragment; website addresses business customers.
A11: FBD-EW-HSPCB-HIST-022 | B11: AV Green Solutions Pvt Ltd. | C11: Dismantler | D11: Plot No. 274, Sector-24, Industrial Area, Faridabad | G11: https://hspcb.gov.in/uploads/pages/ewaster_66ac829eb3965.pdf | H11: HSPCB PDF: List of E-waste Recyclers / Dismantler (historical record; current validity not established) | I11: 46304 | J11: Not established from accessible record | K11: unknown_needs_current_verification | L11: official_historical_record_only | M11: official_document_search_result | N11: HSPCB PDF row 22 (indexed search extract) | O11: not_checked | P11: pending_clarification | Q11: not_checked | R11: pending | T11: False | U11: False | V11: Do not publish as currently authorized until current CPCB registration/status and service details are verified. | W11: =IF(COUNTIFS('Verification Evidence'!$A$5:$A$94,$A11,'Verification Evidence'!$D$5:$D$94,"conflicting")>0,"conflicting",IF(COUNTIFS('Verification Evidence'!$A$5:$A$94,$A11,'Verification Evidence'!$D$5:$D$94,"verified")+COUNTIFS('Verification Evidence'!$A$5:$A$94,$A11,'Verification Evidence'!$D$5:$D$94,"not_applicable")=9,"verified",IF(COUNTIFS('Verification Evidence'!$A$5:$A$94,$A11,'Verification Evidence'!$C$5:$C$94,"Current registration / authorization",'Verification Evidence'!$D$5:$D$94,"verified")+COUNTIFS('Verification Evidence'!$A$5:$A$94,$A11,'Verification Evidence'!$C$5:$C$94,"Current registration / authorization",'Verification Evidence'!$D$5:$D$94,"partially_verified")+COUNTIFS('Verification Evidence'!$A$5:$A$94,$A11,'Verification Evidence'!$C$5:$C$94,"Operating at recorded address",'Verification Evidence'!$D$5:$D$94,"verified")+COUNTIFS('Verification Evidence'!$A$5:$A$94,$A11,'Verification Evidence'!$C$5:$C$94,"Operating at recorded address",'Verification Evidence'!$D$5:$D$94,"partially_verified")>0,"partially_verified","unverified"))) -> unverified | X11: =IFERROR(INDEX('Verification Evidence'!$D$5:$D$94,MATCH($A11&"|Current registration / authorization",'Verification Evidence'!$P$5:$P$94,0)),"MISSING") -> unverified | Y11: =IFERROR(INDEX('Verification Evidence'!$D$5:$D$94,MATCH($A11&"|Household (individual) intake",'Verification Evidence'!$P$5:$P$94,0)),"MISSING") -> unverified | Z11: 37 | AA11: 381 | AB11: Only a machinery-supplier client list supports existence; no operating evidence.
A12: FBD-EW-HSPCB-HIST-023 | B12: Re Chakra Waste Management LLP. | C12: Recycler | D12: Plot No. 18, Sector-6, Faridabad | G12: https://hspcb.gov.in/uploads/pages/ewaster_66ac829eb3965.pdf | H12: HSPCB PDF: List of E-waste Recyclers / Dismantler (historical record; current validity not established) | I12: 46304 | J12: Not established from accessible record | K12: unknown_needs_current_verification | L12: official_historical_record_only | M12: official_document_search_result | N12: HSPCB PDF row 23 (indexed search extract) | O12: not_checked | P12: pending_clarification | Q12: not_checked | R12: pending | T12: False | U12: False | V12: Do not publish as currently authorized until current CPCB registration/status and service details are verified. | W12: =IF(COUNTIFS('Verification Evidence'!$A$5:$A$94,$A12,'Verification Evidence'!$D$5:$D$94,"conflicting")>0,"conflicting",IF(COUNTIFS('Verification Evidence'!$A$5:$A$94,$A12,'Verification Evidence'!$D$5:$D$94,"verified")+COUNTIFS('Verification Evidence'!$A$5:$A$94,$A12,'Verification Evidence'!$D$5:$D$94,"not_applicable")=9,"verified",IF(COUNTIFS('Verification Evidence'!$A$5:$A$94,$A12,'Verification Evidence'!$C$5:$C$94,"Current registration / authorization",'Verification Evidence'!$D$5:$D$94,"verified")+COUNTIFS('Verification Evidence'!$A$5:$A$94,$A12,'Verification Evidence'!$C$5:$C$94,"Current registration / authorization",'Verification Evidence'!$D$5:$D$94,"partially_verified")+COUNTIFS('Verification Evidence'!$A$5:$A$94,$A12,'Verification Evidence'!$C$5:$C$94,"Operating at recorded address",'Verification Evidence'!$D$5:$D$94,"verified")+COUNTIFS('Verification Evidence'!$A$5:$A$94,$A12,'Verification Evidence'!$C$5:$C$94,"Operating at recorded address",'Verification Evidence'!$D$5:$D$94,"partially_verified")>0,"partially_verified","unverified"))) -> partially_verified | X12: =IFERROR(INDEX('Verification Evidence'!$D$5:$D$94,MATCH($A12&"|Current registration / authorization",'Verification Evidence'!$P$5:$P$94,0)),"MISSING") -> partially_verified | Y12: =IFERROR(INDEX('Verification Evidence'!$D$5:$D$94,MATCH($A12&"|Household (individual) intake",'Verification Evidence'!$P$5:$P$94,0)),"MISSING") -> unverified | Z12: 38 | AA12: 8931 | AB12: Plot number truncated in 2025 fragment; household intake not evidenced (brand take-back only).
A13: FBD-EW-HSPCB-HIST-024 | B13: CLG Projects LLP | C13: Dismantler | D13: Plot No. 75-76, Sector-59, Pragati Vihar, Ballabgarh, Faridabad | G13: https://hspcb.gov.in/uploads/pages/ewaster_66ac829eb3965.pdf | H13: HSPCB PDF: List of E-waste Recyclers / Dismantler (historical record; current validity not established) | I13: 46304 | J13: Not established from accessible record | K13: unknown_needs_current_verification | L13: official_historical_record_only | M13: official_document_search_result | N13: HSPCB PDF row 24 (indexed search extract) | O13: not_checked | P13: pending_clarification | Q13: not_checked | R13: pending | T13: False | U13: False | V13: Do not publish as currently authorized until current CPCB registration/status and service details are verified. | W13: =IF(COUNTIFS('Verification Evidence'!$A$5:$A$94,$A13,'Verification Evidence'!$D$5:$D$94,"conflicting")>0,"conflicting",IF(COUNTIFS('Verification Evidence'!$A$5:$A$94,$A13,'Verification Evidence'!$D$5:$D$94,"verified")+COUNTIFS('Verification Evidence'!$A$5:$A$94,$A13,'Verification Evidence'!$D$5:$D$94,"not_applicable")=9,"verified",IF(COUNTIFS('Verification Evidence'!$A$5:$A$94,$A13,'Verification Evidence'!$C$5:$C$94,"Current registration / authorization",'Verification Evidence'!$D$5:$D$94,"verified")+COUNTIFS('Verification Evidence'!$A$5:$A$94,$A13,'Verification Evidence'!$C$5:$C$94,"Current registration / authorization",'Verification Evidence'!$D$5:$D$94,"partially_verified")+COUNTIFS('Verification Evidence'!$A$5:$A$94,$A13,'Verification Evidence'!$C$5:$C$94,"Operating at recorded address",'Verification Evidence'!$D$5:$D$94,"verified")+COUNTIFS('Verification Evidence'!$A$5:$A$94,$A13,'Verification Evidence'!$C$5:$C$94,"Operating at recorded address",'Verification Evidence'!$D$5:$D$94,"partially_verified")>0,"partially_verified","unverified"))) -> unverified | X13: =IFERROR(INDEX('Verification Evidence'!$D$5:$D$94,MATCH($A13&"|Current registration / authorization",'Verification Evidence'!$P$5:$P$94,0)),"MISSING") -> unverified | Y13: =IFERROR(INDEX('Verification Evidence'!$D$5:$D$94,MATCH($A13&"|Household (individual) intake",'Verification Evidence'!$P$5:$P$94,0)),"MISSING") -> unverified | Z13: 39 | AA13: 450 | AB13: No independent web presence found.
A14: FBD-EW-HSPCB-HIST-025 | B14: SSL E Waste Management LLP | C14: Dismantler | D14: Plot No. 410, Sector-68, IMT, Faridabad | G14: https://hspcb.gov.in/uploads/pages/ewaster_66ac829eb3965.pdf | H14: HSPCB PDF: List of E-waste Recyclers / Dismantler (historical record; current validity not established) | I14: 46304 | J14: Not established from accessible record | K14: unknown_needs_current_verification | L14: official_historical_record_only | M14: official_document_search_result | N14: HSPCB PDF row 25 (indexed search extract) | O14: not_checked | P14: pending_clarification | Q14: not_checked | R14: pending | T14: False | U14: False | V14: Do not publish as currently authorized until current CPCB registration/status and service details are verified. | W14: =IF(COUNTIFS('Verification Evidence'!$A$5:$A$94,$A14,'Verification Evidence'!$D$5:$D$94,"conflicting")>0,"conflicting",IF(COUNTIFS('Verification Evidence'!$A$5:$A$94,$A14,'Verification Evidence'!$D$5:$D$94,"verified")+COUNTIFS('Verification Evidence'!$A$5:$A$94,$A14,'Verification Evidence'!$D$5:$D$94,"not_applicable")=9,"verified",IF(COUNTIFS('Verification Evidence'!$A$5:$A$94,$A14,'Verification Evidence'!$C$5:$C$94,"Current registration / authorization",'Verification Evidence'!$D$5:$D$94,"verified")+COUNTIFS('Verification Evidence'!$A$5:$A$94,$A14,'Verification Evidence'!$C$5:$C$94,"Current registration / authorization",'Verification Evidence'!$D$5:$D$94,"partially_verified")+COUNTIFS('Verification Evidence'!$A$5:$A$94,$A14,'Verification Evidence'!$C$5:$C$94,"Operating at recorded address",'Verification Evidence'!$D$5:$D$94,"verified")+COUNTIFS('Verification Evidence'!$A$5:$A$94,$A14,'Verification Evidence'!$C$5:$C$94,"Operating at recorded address",'Verification Evidence'!$D$5:$D$94,"partially_verified")>0,"partially_verified","unverified"))) -> unverified | X14: =IFERROR(INDEX('Verification Evidence'!$D$5:$D$94,MATCH($A14&"|Current registration / authorization",'Verification Evidence'!$P$5:$P$94,0)),"MISSING") -> unverified | Y14: =IFERROR(INDEX('Verification Evidence'!$D$5:$D$94,MATCH($A14&"|Household (individual) intake",'Verification Evidence'!$P$5:$P$94,0)),"MISSING") -> unverified | Z14: 40 | AA14: 423 | AB14: No independent web presence found.

Sheet Verification Evidence
A1: Verification Evidence
A2: One row per candidate per verification check (10 candidates x 9 checks). Researched on 2026-10-10 from the sources cited; nothing here is a confirmation by the facility.
A3: Header colours: blue = researched findings, brown = human-entered (blank until a reviewer fills it). 'NO EVIDENCE LOCATED' means searched and nothing found - it is not a negative finding. Sort/filter with the column arrows.
A4: Provider ID | B4: Provider name | C4: Verification category | D4: Status | E4: Evidence source | F4: Evidence URL | G4: Additional sources | H4: Evidence excerpt / finding | I4: Date accessed | J4: Confidence | K4: Confidence rationale | L4: Contradictions / limitations | M4: Human follow-up required | N4: Next action | O4: Reviewer notes (human-entered) | P4: Lookup key
A5: FBD-EW-HSPCB-HIST-016 | B5: Endeavor Re-processor and Recyclers India | C5: Entity match to historical record | D5: partially_verified | E5: CPCB list of authorised dismantlers/recyclers 'As on 08-06-2023' (mirror hosted at ndmc.gov.in; Haryana section read in full) | F5: https://www.ndmc.gov.in/pdf/cpcb_approved_list_of_e-waste_recyclers_dismantler.pdf | H5: Haryana serial 12: 'M/s Endeavor Re-processor and Recyclers India, Plot no. 323, Sec-24, industrial Area, Faridabad (Not available on website)'; capacity 365 MTA. | I5: 46305 | J5: medium | K5: Name and address match the CSV in an independent compilation of the same authorisation data; HSPCB PDF row 16 itself could not be read. | L5: Hosted on a third-party mirror (ndmc.gov.in), not the CPCB origin server; document title reads 'Rules, 2026', an apparent typo. Plot 323, Sec-24 is also listed for Naturevolt (HIST-021, 'Part-IV'). The similarly named 'Endeavor Recyclers India Private Limited' (Rohtak, serial 43) has a different address and was NOT matched. | M5: human_verification_required | N5: Open the original HSPCB PDF, confirm the row text and number, and compare with the CSV. | P5: FBD-EW-HSPCB-HIST-016|Entity match to historical record
A6: FBD-EW-HSPCB-HIST-016 | B6: Endeavor Re-processor and Recyclers India | C6: Current registration / authorization | D6: unverified | E6: CPCB list of authorised dismantlers/recyclers 'As on 08-06-2023' (mirror hosted at ndmc.gov.in; Haryana section read in full) | F6: https://www.ndmc.gov.in/pdf/cpcb_approved_list_of_e-waste_recyclers_dismantler.pdf | G6: https://www.eprewaste.cpcb.gov.in/ | H6: Listed in the 08-06-2023 CPCB list with the annotation '(Not available on website)'; no later record located. | I6: 46305 | J6: low | K6: A 2023 listing is not current authorization, and the annotation (undefined in the document) is a flag, not a finding. | L6: CPCB EPR portal and hspcb.gov.in (including the original HSPCB PDF) disallow automated access, so current registration, CTO and EPR status could not be checked at the authoritative source. The CPCB list is dated 08-06-2023 (over three years before this review). | M6: human_verification_required | N6: Look up the entity on the CPCB EPR portal (record registration number, validity, date checked) and ask HSPCB Faridabad Regional Office for the CTO/authorisation number and validity. | P6: FBD-EW-HSPCB-HIST-016|Current registration / authorization
A7: FBD-EW-HSPCB-HIST-016 | B7: Endeavor Re-processor and Recyclers India | C7: Operating at recorded address | D7: unverified | E7: CPCB list of authorised dismantlers/recyclers 'As on 08-06-2023' (mirror hosted at ndmc.gov.in; Haryana section read in full) | F7: https://www.ndmc.gov.in/pdf/cpcb_approved_list_of_e-waste_recyclers_dismantler.pdf | H7: Only the list entry; no operating evidence located. The same plot number appears for another entity (HIST-021). | I7: 46305 | J7: low | K7: Possible shared premises or a transcription difference cannot be resolved from the sources read. | L7: The CPCB list is dated 08-06-2023 (over three years before this review). | M7: human_verification_required | N7: Confirm the current operating address with the facility or HSPCB Faridabad Regional Office. | P7: FBD-EW-HSPCB-HIST-016|Operating at recorded address
A8: FBD-EW-HSPCB-HIST-016 | B8: Endeavor Re-processor and Recyclers India | C8: Household (individual) intake | D8: unverified | E8: NO EVIDENCE LOCATED | H8: NO EVIDENCE LOCATED | I8: 46305 | J8: low | K8: No source located for this specific claim. | M8: human_verification_required | N8: Ask the facility whether it accepts e-waste directly from individual households. | P8: FBD-EW-HSPCB-HIST-016|Household (individual) intake
A9: FBD-EW-HSPCB-HIST-016 | B9: Endeavor Re-processor and Recyclers India | C9: Drop-off / collection / pickup service | D9: unverified | E9: NO EVIDENCE LOCATED | H9: NO EVIDENCE LOCATED | I9: 46305 | J9: low | K9: No source located for this specific claim. | M9: human_verification_required | N9: Ask whether it offers household drop-off, collection or pickup (where, how, any charge or minimum). | P9: FBD-EW-HSPCB-HIST-016|Drop-off / collection / pickup service
A10: FBD-EW-HSPCB-HIST-016 | B10: Endeavor Re-processor and Recyclers India | C10: Accepted item categories | D10: unverified | E10: NO EVIDENCE LOCATED | H10: NO EVIDENCE LOCATED | I10: 46305 | J10: low | K10: No source located for this specific claim. | M10: human_verification_required | N10: Obtain a written list of the e-waste item categories accepted from households. | P10: FBD-EW-HSPCB-HIST-016|Accepted item categories
A11: FBD-EW-HSPCB-HIST-016 | B11: Endeavor Re-processor and Recyclers India | C11: Contact channel | D11: unverified | E11: NO EVIDENCE LOCATED | H11: NO EVIDENCE LOCATED | I11: 46305 | J11: low | K11: No source located for this specific claim. | M11: human_verification_required | N11: Obtain an official contact channel in writing and confirm it may be shown publicly. | P11: FBD-EW-HSPCB-HIST-016|Contact channel
A12: FBD-EW-HSPCB-HIST-016 | B12: Endeavor Re-processor and Recyclers India | C12: Operating hours | D12: unverified | E12: NO EVIDENCE LOCATED | H12: NO EVIDENCE LOCATED | I12: 46305 | J12: low | K12: No source located for this specific claim. | M12: human_verification_required | N12: Ask for intake/operating hours (days, times, holidays). | P12: FBD-EW-HSPCB-HIST-016|Operating hours
A13: FBD-EW-HSPCB-HIST-016 | B13: Endeavor Re-processor and Recyclers India | C13: Listing & reuse permission | D13: unverified | E13: CPCB EPR portal and HSPCB site - automated access disallowed | F13: https://www.eprewaste.cpcb.gov.in/ | H13: Source licence and listing permission remain 'not_checked' / 'pending_clarification' in the input; no consent or reuse terms were located. | I13: 46305 | J13: low | K13: No documented permission or licence terms found. | L13: Reuse terms of the CPCB list, the HSPCB PDF and the 2025 tribunal filing were not established. | M13: human_verification_required | N13: Request documented consent to be listed publicly and confirm HSPCB/CPCB data reuse terms (licence, attribution). | P13: FBD-EW-HSPCB-HIST-016|Listing & reuse permission
A14: FBD-EW-HSPCB-HIST-017 | B14: A to Z E-waste Solutions | C14: Entity match to historical record | D14: unverified | E14: CPCB list of authorised dismantlers/recyclers 'As on 08-06-2023' (mirror hosted at ndmc.gov.in; Haryana section read in full) | F14: https://www.ndmc.gov.in/pdf/cpcb_approved_list_of_e-waste_recyclers_dismantler.pdf | H14: Not present among the 43 Haryana entries of the 08-06-2023 CPCB list; name located only in the input CSV. Web searches returned no company page or directory entry. | I14: 46305 | J14: low | K14: No independent source matches this name; HSPCB PDF row 17 could not be read. | L14: Address says 'Pargiti Vihar'; other entries in the same area read 'Pragati Vihar' (likely a transcription variant, unconfirmed - not corrected). Hosted on a third-party mirror (ndmc.gov.in), not the CPCB origin server; document title reads 'Rules, 2026', an apparent typo. | M14: human_verification_required | N14: Open the original HSPCB PDF, confirm the row text and number, and compare with the CSV. | P14: FBD-EW-HSPCB-HIST-017|Entity match to historical record
A15: FBD-EW-HSPCB-HIST-017 | B15: A to Z E-waste Solutions | C15: Current registration / authorization | D15: unverified | E15: CPCB EPR portal and HSPCB site - automated access disallowed | F15: https://www.eprewaste.cpcb.gov.in/ | H15: NO EVIDENCE LOCATED (entity not found in accessible sources) | I15: 46305 | J15: low | K15: Entity could not be matched, so no registration lookup is meaningful yet. | L15: CPCB EPR portal and hspcb.gov.in (including the original HSPCB PDF) disallow automated access, so current registration, CTO and EPR status could not be checked at the authoritative source. | M15: human_verification_required | N15: Look up the entity on the CPCB EPR portal (record registration number, validity, date checked) and ask HSPCB Faridabad Regional Office for the CTO/authorisation number and validity. | P15: FBD-EW-HSPCB-HIST-017|Current registration / authorization
A16: FBD-EW-HSPCB-HIST-017 | B16: A to Z E-waste Solutions | C16: Operating at recorded address | D16: unverified | E16: NO EVIDENCE LOCATED | H16: No evidence beyond the list entry itself; no operating or site evidence located. | I16: 46305 | J16: low | K16: No source located for this specific claim. | M16: human_verification_required | N16: Confirm the current operating address with the facility or HSPCB Faridabad Regional Office. | P16: FBD-EW-HSPCB-HIST-017|Operating at recorded address
A17: FBD-EW-HSPCB-HIST-017 | B17: A to Z E-waste Solutions | C17: Household (individual) intake | D17: unverified | E17: NO EVIDENCE LOCATED | H17: NO EVIDENCE LOCATED | I17: 46305 | J17: low | K17: No source located for this specific claim. | M17: human_verification_required | N17: Ask the facility whether it accepts e-waste directly from individual households. | P17: FBD-EW-HSPCB-HIST-017|Household (individual) intake
A18: FBD-EW-HSPCB-HIST-017 | B18: A to Z E-waste Solutions | C18: Drop-off / collection / pickup service | D18: unverified | E18: NO EVIDENCE LOCATED | H18: NO EVIDENCE LOCATED | I18: 46305 | J18: low | K18: No source located for this specific claim. | M18: human_verification_required | N18: Ask whether it offers household drop-off, collection or pickup (where, how, any charge or minimum). | P18: FBD-EW-HSPCB-HIST-017|Drop-off / collection / pickup service
A19: FBD-EW-HSPCB-HIST-017 | B19: A to Z E-waste Solutions | C19: Accepted item categories | D19: unverified | E19: NO EVIDENCE LOCATED | H19: NO EVIDENCE LOCATED | I19: 46305 | J19: low | K19: No source located for this specific claim. | M19: human_verification_required | N19: Obtain a written list of the e-waste item categories accepted from households. | P19: FBD-EW-HSPCB-HIST-017|Accepted item categories
A20: FBD-EW-HSPCB-HIST-017 | B20: A to Z E-waste Solutions | C20: Contact channel | D20: unverified | E20: NO EVIDENCE LOCATED | H20: NO EVIDENCE LOCATED | I20: 46305 | J20: low | K20: No source located for this specific claim. | M20: human_verification_required | N20: Obtain an official contact channel in writing and confirm it may be shown publicly. | P20: FBD-EW-HSPCB-HIST-017|Contact channel
A21: FBD-EW-HSPCB-HIST-017 | B21: A to Z E-waste Solutions | C21: Operating hours | D21: unverified | E21: NO EVIDENCE LOCATED | H21: NO EVIDENCE LOCATED | I21: 46305 | J21: low | K21: No source located for this specific claim. | M21: human_verification_required | N21: Ask for intake/operating hours (days, times, holidays). | P21: FBD-EW-HSPCB-HIST-017|Operating hours
A22: FBD-EW-HSPCB-HIST-017 | B22: A to Z E-waste Solutions | C22: Listing & reuse permission | D22: unverified | E22: CPCB EPR portal and HSPCB site - automated access disallowed | F22: https://www.eprewaste.cpcb.gov.in/ | H22: Source licence and listing permission remain 'not_checked' / 'pending_clarification' in the input; no consent or reuse terms were located. | I22: 46305 | J22: low | K22: No documented permission or licence terms found. | L22: Reuse terms of the CPCB list, the HSPCB PDF and the 2025 tribunal filing were not established. | M22: human_verification_required | N22: Request documented consent to be listed publicly and confirm HSPCB/CPCB data reuse terms (licence, attribution). | P22: FBD-EW-HSPCB-HIST-017|Listing & reuse permission
A23: FBD-EW-HSPCB-HIST-018 | B23: E-waste Solutions | C23: Entity match to historical record | D23: partially_verified | E23: CPCB list of authorised dismantlers/recyclers 'As on 08-06-2023' (mirror hosted at ndmc.gov.in; Haryana section read in full) | F23: https://www.ndmc.gov.in/pdf/cpcb_approved_list_of_e-waste_recyclers_dismantler.pdf | G23: https://hisenseme.com/assets/assets/img/certificate/E-waste_Management.pdf https://m.indiamart.com/ewaste-solution https://www.greentribunal.gov.in/sites/default/files/news_updates/Reply%20of%20HSPCB%20in%20OA%20No.%2088%20of%202025%20(Devidas%20Khatri%20Vs.%20UOI%20%26%20Ors.).pdf | H23: Haryana serial 13: 'M/s E-waste Solutions, Industrial Shed, 1A, Industrial Estate, Sec-6, Faridabad'; 1000 MTA. A Hisense PDF and an IndiaMART listing give the same Shed 1A, Industrial Estate, Sector 6, Faridabad 121006 address. | I23: 46305 | J23: medium | K23: Name and address agree across the CPCB list and two third-party documents. | L23: Generic name. A 2025 HSPCB annexure fragment lists a 'M/s E waste Solutions, Khasra No. ...' (row 12) that appears to be a different address; the two must not be conflated. Hosted on a third-party mirror (ndmc.gov.in), not the CPCB origin server; document title reads 'Rules, 2026', an apparent typo. | M23: human_verification_required | N23: Open the original HSPCB PDF, confirm the row text and number, and compare with the CSV. | P23: FBD-EW-HSPCB-HIST-018|Entity match to historical record
A24: FBD-EW-HSPCB-HIST-018 | B24: E-waste Solutions | C24: Current registration / authorization | D24: partially_verified | E24: CPCB list of authorised dismantlers/recyclers 'As on 08-06-2023' (mirror hosted at ndmc.gov.in; Haryana section read in full) | F24: https://www.ndmc.gov.in/pdf/cpcb_approved_list_of_e-waste_recyclers_dismantler.pdf | G24: https://hisenseme.com/assets/assets/img/certificate/E-waste_Management.pdf https://www.greentribunal.gov.in/sites/default/files/news_updates/Reply%20of%20HSPCB%20in%20OA%20No.%2088%20of%202025%20(Devidas%20Khatri%20Vs.%20UOI%20%26%20Ors.).pdf https://www.eprewaste.cpcb.gov.in/ | H24: Listed in the 08-06-2023 CPCB list. Hisense's PDF states its partner is 'registered with Haryana State Pollution Control Board' (company claim, undated). | I24: 46305 | J24: low | K24: Two independent mentions, but one is a brand's self-statement and the list is old. | L24: CPCB EPR portal and hspcb.gov.in (including the original HSPCB PDF) disallow automated access, so current registration, CTO and EPR status could not be checked at the authoritative source. The CPCB list is dated 08-06-2023 (over three years before this review). No CTO number or validity was legible. | M24: human_verification_required | N24: Look up the entity on the CPCB EPR portal (record registration number, validity, date checked) and ask HSPCB Faridabad Regional Office for the CTO/authorisation number and validity. | P24: FBD-EW-HSPCB-HIST-018|Current registration / authorization
A25: FBD-EW-HSPCB-HIST-018 | B25: E-waste Solutions | C25: Operating at recorded address | D25: partially_verified | E25: Hisense: E-waste Management (corporate PDF, undated) | F25: https://hisenseme.com/assets/assets/img/certificate/E-waste_Management.pdf | G25: https://m.indiamart.com/ewaste-solution | H25: Hisense PDF: partner's plant at 'Industrial area 1A, Industrial Estate, Sector 6, Faridabad, Haryana - 121006'. IndiaMART lists 'Shed 1A, Industrial Estate, Sector 6'. | I25: 46305 | J25: low | K25: Address repeated by third parties; no dated evidence of current operation. | L25: Both documents are undated; no site visit. | M25: human_verification_required | N25: Confirm the current operating address with the facility or HSPCB Faridabad Regional Office. | P25: FBD-EW-HSPCB-HIST-018|Operating at recorded address
A26: FBD-EW-HSPCB-HIST-018 | B26: E-waste Solutions | C26: Household (individual) intake | D26: unverified | E26: Hisense: E-waste Management (corporate PDF, undated) | F26: https://hisenseme.com/assets/assets/img/certificate/E-waste_Management.pdf | H26: Hisense describes channelising its own customers' e-waste through the partner; no statement that individual households may deliver directly. | I26: 46305 | J26: low | K26: Brand take-back arrangement is not evidence of open household intake. | L26: Scope of any household service is unknown. | M26: human_verification_required | N26: Ask the facility whether it accepts e-waste directly from individual households. | P26: FBD-EW-HSPCB-HIST-018|Household (individual) intake
A27: FBD-EW-HSPCB-HIST-018 | B27: E-waste Solutions | C27: Drop-off / collection / pickup service | D27: partially_verified | E27: IndiaMART seller listing 'E Waste Solutions', Faridabad (third-party directory, self-published) | F27: https://m.indiamart.com/ewaste-solution | G27: https://hisenseme.com/assets/assets/img/certificate/E-waste_Management.pdf | H27: IndiaMART lists 'Schedule Pickup' and 'Material Collection'; Hisense PDF refers to an agreement for reverse logistics to the facility. | I27: 46305 | J27: low | K27: A pickup/collection service appears to exist, but both sources are third-party and say nothing about households. | L27: Directory entries are self-published; coverage area and eligibility unknown. | M27: human_verification_required | N27: Ask whether it offers household drop-off, collection or pickup (where, how, any charge or minimum). | P27: FBD-EW-HSPCB-HIST-018|Drop-off / collection / pickup service
A28: FBD-EW-HSPCB-HIST-018 | B28: E-waste Solutions | C28: Accepted item categories | D28: unverified | E28: IndiaMART seller listing 'E Waste Solutions', Faridabad (third-party directory, self-published) | F28: https://m.indiamart.com/ewaste-solution | H28: Directory lists trade categories (plastic scrap, ferrous scrap, battery scrap) - these are not an e-waste item list. | I28: 46305 | J28: low | K28: No explicit e-waste accepted-items statement. | L28: Do not treat scrap trade codes as accepted item categories. | M28: human_verification_required | N28: Obtain a written list of the e-waste item categories accepted from households. | P28: FBD-EW-HSPCB-HIST-018|Accepted item categories
A29: FBD-EW-HSPCB-HIST-018 | B29: E-waste Solutions | C29: Contact channel | D29: unverified | E29: IndiaMART seller listing 'E Waste Solutions', Faridabad (third-party directory, self-published) | F29: https://m.indiamart.com/ewaste-solution | H29: Only a third-party directory shows phone numbers and a partner name; none copied here. No official contact channel was established. | I29: 46305 | J29: low | K29: Directory contacts are not an official, confirmed channel. | M29: human_verification_required | N29: Obtain an official contact channel in writing and confirm it may be shown publicly. | P29: FBD-EW-HSPCB-HIST-018|Contact channel
A30: FBD-EW-HSPCB-HIST-018 | B30: E-waste Solutions | C30: Operating hours | D30: unverified | E30: IndiaMART seller listing 'E Waste Solutions', Faridabad (third-party directory, self-published) | F30: https://m.indiamart.com/ewaste-solution | H30: Directory displays hours text ('Closes 7 PM'); this is a self-published listing, not confirmed operating or intake hours. | I30: 46305 | J30: low | K30: Not authoritative. | M30: human_verification_required | N30: Ask for intake/operating hours (days, times, holidays). | P30: FBD-EW-HSPCB-HIST-018|Operating hours
A31: FBD-EW-HSPCB-HIST-018 | B31: E-waste Solutions | C31: Listing & reuse permission | D31: unverified | E31: CPCB EPR portal and HSPCB site - automated access disallowed | F31: https://www.eprewaste.cpcb.gov.in/ | H31: Source licence and listing permission remain 'not_checked' / 'pending_clarification' in the input; no consent or reuse terms were located. | I31: 46305 | J31: low | K31: No documented permission or licence terms found. | L31: Reuse terms of the CPCB list, the HSPCB PDF and the 2025 tribunal filing were not established. | M31: human_verification_required | N31: Request documented consent to be listed publicly and confirm HSPCB/CPCB data reuse terms (licence, attribution). | P31: FBD-EW-HSPCB-HIST-018|Listing & reuse permission
A32: FBD-EW-HSPCB-HIST-019 | B32: V S Enterprises | C32: Entity match to historical record | D32: partially_verified | E32: CPCB list of authorised dismantlers/recyclers 'As on 08-06-2023' (mirror hosted at ndmc.gov.in; Haryana section read in full) | F32: https://www.ndmc.gov.in/pdf/cpcb_approved_list_of_e-waste_recyclers_dismantler.pdf | H32: Haryana serial 14: 'M/s V S Enterprises, Plot no. 9, Pragati Vihar, Sector-59, Faridabad (Not available on website)'; 300 MTA. | I32: 46305 | J32: medium | K32: Name and address match the CSV; no other source mentions the entity. | L32: Hosted on a third-party mirror (ndmc.gov.in), not the CPCB origin server; document title reads 'Rules, 2026', an apparent typo. | M32: human_verification_required | N32: Open the original HSPCB PDF, confirm the row text and number, and compare with the CSV. | P32: FBD-EW-HSPCB-HIST-019|Entity match to historical record
A33: FBD-EW-HSPCB-HIST-019 | B33: V S Enterprises | C33: Current registration / authorization | D33: unverified | E33: CPCB list of authorised dismantlers/recyclers 'As on 08-06-2023' (mirror hosted at ndmc.gov.in; Haryana section read in full) | F33: https://www.ndmc.gov.in/pdf/cpcb_approved_list_of_e-waste_recyclers_dismantler.pdf | G33: https://www.eprewaste.cpcb.gov.in/ | H33: Listed in the 08-06-2023 CPCB list with the annotation '(Not available on website)'; no later record located. | I33: 46305 | J33: low | K33: A 2023 listing is not current authorization. | L33: CPCB EPR portal and hspcb.gov.in (including the original HSPCB PDF) disallow automated access, so current registration, CTO and EPR status could not be checked at the authoritative source. The CPCB list is dated 08-06-2023 (over three years before this review). | M33: human_verification_required | N33: Look up the entity on the CPCB EPR portal (record registration number, validity, date checked) and ask HSPCB Faridabad Regional Office for the CTO/authorisation number and validity. | P33: FBD-EW-HSPCB-HIST-019|Current registration / authorization
A34: FBD-EW-HSPCB-HIST-019 | B34: V S Enterprises | C34: Operating at recorded address | D34: unverified | E34: NO EVIDENCE LOCATED | H34: No evidence beyond the list entry itself; no operating or site evidence located. | I34: 46305 | J34: low | K34: No source located for this specific claim. | M34: human_verification_required | N34: Confirm the current operating address with the facility or HSPCB Faridabad Regional Office. | P34: FBD-EW-HSPCB-HIST-019|Operating at recorded address
A35: FBD-EW-HSPCB-HIST-019 | B35: V S Enterprises | C35: Household (individual) intake | D35: unverified | E35: NO EVIDENCE LOCATED | H35: NO EVIDENCE LOCATED | I35: 46305 | J35: low | K35: No source located for this specific claim. | M35: human_verification_required | N35: Ask the facility whether it accepts e-waste directly from individual households. | P35: FBD-EW-HSPCB-HIST-019|Household (individual) intake
A36: FBD-EW-HSPCB-HIST-019 | B36: V S Enterprises | C36: Drop-off / collection / pickup service | D36: unverified | E36: NO EVIDENCE LOCATED | H36: NO EVIDENCE LOCATED | I36: 46305 | J36: low | K36: No source located for this specific claim. | M36: human_verification_required | N36: Ask whether it offers household drop-off, collection or pickup (where, how, any charge or minimum). | P36: FBD-EW-HSPCB-HIST-019|Drop-off / collection / pickup service
A37: FBD-EW-HSPCB-HIST-019 | B37: V S Enterprises | C37: Accepted item categories | D37: unverified | E37: NO EVIDENCE LOCATED | H37: NO EVIDENCE LOCATED | I37: 46305 | J37: low | K37: No source located for this specific claim. | M37: human_verification_required | N37: Obtain a written list of the e-waste item categories accepted from households. | P37: FBD-EW-HSPCB-HIST-019|Accepted item categories
A38: FBD-EW-HSPCB-HIST-019 | B38: V S Enterprises | C38: Contact channel | D38: unverified | E38: NO EVIDENCE LOCATED | H38: NO EVIDENCE LOCATED | I38: 46305 | J38: low | K38: No source located for this specific claim. | M38: human_verification_required | N38: Obtain an official contact channel in writing and confirm it may be shown publicly. | P38: FBD-EW-HSPCB-HIST-019|Contact channel
A39: FBD-EW-HSPCB-HIST-019 | B39: V S Enterprises | C39: Operating hours | D39: unverified | E39: NO EVIDENCE LOCATED | H39: NO EVIDENCE LOCATED | I39: 46305 | J39: low | K39: No source located for this specific claim. | M39: human_verification_required | N39: Ask for intake/operating hours (days, times, holidays). | P39: FBD-EW-HSPCB-HIST-019|Operating hours
A40: FBD-EW-HSPCB-HIST-019 | B40: V S Enterprises | C40: Listing & reuse permission | D40: unverified | E40: CPCB EPR portal and HSPCB site - automated access disallowed | F40: https://www.eprewaste.cpcb.gov.in/ | H40: Source licence and listing permission remain 'not_checked' / 'pending_clarification' in the input; no consent or reuse terms were located. | I40: 46305 | J40: low | K40: No documented permission or licence terms found. | L40: Reuse terms of the CPCB list, the HSPCB PDF and the 2025 tribunal filing were not established. | M40: human_verification_required | N40: Request documented consent to be listed publicly and confirm HSPCB/CPCB data reuse terms (licence, attribution). | P40: FBD-EW-HSPCB-HIST-019|Listing & reuse permission
...

Sheet Human Verification Queue
A1: Human Verification Queue
A2: Outstanding checks that need a person. Questions are written for the facility or for HSPCB Faridabad Regional Office. Brown headers / cream cells are for the team to fill; nothing is pre-filled as done.
A3: Contact methods appear only where a source supports them (see Contact basis). Blank = no supported channel yet. Consent status stays 'not_requested' until a written confirmation exists; completion status starts 'open'.
A4: Queue ID | B4: Provider ID | C4: Provider name | D4: Check category | E4: Question requiring confirmation | F4: Suggested priority | G4: Responsible party | H4: Contact method (evidence-supported) | I4: Contact basis | J4: Date contacted | K4: Response date | L4: Response / evidence received | M4: Consent status | N4: Follow-up action | O4: Completion status
